<?xml version="1.0"?>
<robot xmlns:xacro="http://ros.org/wiki/xacro">

    <xacro:unless value="$(arg sim_mode)">
        <ros2_control name="RealRobot" type="system">
            <hardware>
                <plugin>diffdrive_arduino/DiffDriveArduinoHardware</plugin>
            </hardware>

            <joint name="$l_wheel_joints" type="continuous">
                <parent link="chassis"/>
                <child link="${prefix}_wheel_link"/>
                <origin xyz="${l_r*wheel_x_displacement} ${f_b*wheel_y_displacement} ${wheel_z_displacement}" rpy="0 0 0"/>
                <axis xyz="0 1 0"/>
            </joint>

            <joint name="$r_wheel_joints" type="continuous">
                <parent link="chassis"/>
                <child link="${prefix}_wheel_link"/>
                <origin xyz="${l_r*wheel_x_displacement} ${f_b*wheel_y_displacement} ${wheel_z_displacement}" rpy="0 0 0"/>
                <axis xyz="0 1 0"/>
            </joint>
        </ros2_control>

        <!-- IMU sensor--> 
        <!-- <ros2_control name='da_imu' type='sensor'>
            <hardware>
                <plugin>IMU SENSOR PLUGIN HERE</plugin>
                <param name='sensor_name'>SAME AS IN controllers.yaml</param>
                <param name='frame_id'>imu_link</param>
            </hardware>
            <sensor name=''>
                STATE INTERFACES HERE
            </sensor>
        </ros2_control>  -->
    </xacro:unless>

    <xacro:if value="$(arg sim_mode)">
        <ros2_control name='GazeboSystem' type='system'>
            <hardware>
                <plugin>gazebo_ros2_control/GazeboSystem</plugin>
            </hardware>

            <joint name="b_l_wheel_joint">
                <command_interface name="velocity">
                    <param name="min">-10</param>
                    <param name="max">10</param>
                </command_interface>
                <state_interface name="position" />
                <state_interface name="velocity" />
            </joint>

            <joint name="b_r_wheel_joint">
                <command_interface name="velocity">
                    <param name="min">-10</param>
                    <param name="max">10</param>
                </command_interface>
                <state_interface name="position" />
                <state_interface name="velocity" />
            </joint>

            <joint name="f_l_wheel_joint">
                <command_interface name="velocity">
                    <param name="min">-10</param>
                    <param name="max">10</param>
                </command_interface>
                <state_interface name="position" />
                <state_interface name="velocity" />
            </joint>
            
            <joint name="f_r_wheel_joint">
                <command_interface name="velocity">
                    <param name="min">-10</param>
                    <param name="max">10</param>
                </command_interface>
                <state_interface name="position" />
                <state_interface name="velocity" />
            </joint>
        </ros2_control>
    </xacro:if>

    <gazebo>
        <plugin filename="libgazebo_ros2_control.so" name="gazebo_ros2_control">
            <parameters>$(find secbot_description)/config/controllers.yaml</parameters>
        </plugin>
    </gazebo>
</robot>